news.rst:64: [broken] https://github.com/bloomberg/pytest-memray/issues/10: HTTPSConnectionPool(host='github.com', port=443): Max retries exceeded with url: /bloomberg/pytest-memray/issues/10 (Caused by SSLError(SSLCertVerificationError(1, '[SSL: CERTIFICATE_VERIFY_FAILED] certificate verify failed: self signed certificate in certificate chain (_ssl.c:1002)')))
usage.rst:101: [broken] https://bloomberg.github.io/memray/getting_started.html: HTTPSConnectionPool(host='bloomberg.github.io', port=443): Max retries exceeded with url: /memray/getting_started.html (Caused by SSLError(SSLCertVerificationError(1, '[SSL: CERTIFICATE_VERIFY_FAILED] certificate verify failed: self signed certificate in certificate chain (_ssl.c:1002)')))
news.rst:56: [broken] https://github.com/ChaoticRoman: HTTPSConnectionPool(host='github.com', port=443): Max retries exceeded with url: /ChaoticRoman (Caused by SSLError(SSLCertVerificationError(1, '[SSL: CERTIFICATE_VERIFY_FAILED] certificate verify failed: self signed certificate in certificate chain (_ssl.c:1002)')))
news.rst:66: [broken] https://github.com/bloomberg/pytest-memray/issues/11: HTTPSConnectionPool(host='github.com', port=443): Max retries exceeded with url: /bloomberg/pytest-memray/issues/11 (Caused by SSLError(SSLCertVerificationError(1, '[SSL: CERTIFICATE_VERIFY_FAILED] certificate verify failed: self signed certificate in certificate chain (_ssl.c:1002)')))
news.rst:54: [broken] https://github.com/bloomberg/pytest-memray/issues/12: HTTPSConnectionPool(host='github.com', port=443): Max retries exceeded with url: /bloomberg/pytest-memray/issues/12 (Caused by SSLError(SSLCertVerificationError(1, '[SSL: CERTIFICATE_VERIFY_FAILED] certificate verify failed: self signed certificate in certificate chain (_ssl.c:1002)')))
news.rst:75: [broken] https://github.com/bloomberg/pytest-memray/issues/20: HTTPSConnectionPool(host='github.com', port=443): Max retries exceeded with url: /bloomberg/pytest-memray/issues/20 (Caused by SSLError(SSLCertVerificationError(1, '[SSL: CERTIFICATE_VERIFY_FAILED] certificate verify failed: self signed certificate in certificate chain (_ssl.c:1002)')))
news.rst:41: [broken] https://github.com/bloomberg/pytest-memray/issues/18: HTTPSConnectionPool(host='github.com', port=443): Max retries exceeded with url: /bloomberg/pytest-memray/issues/18 (Caused by SSLError(SSLCertVerificationError(1, '[SSL: CERTIFICATE_VERIFY_FAILED] certificate verify failed: self signed certificate in certificate chain (_ssl.c:1002)')))
news.rst:55: [broken] https://github.com/bloomberg/pytest-memray/issues/26: HTTPSConnectionPool(host='github.com', port=443): Max retries exceeded with url: /bloomberg/pytest-memray/issues/26 (Caused by SSLError(SSLCertVerificationError(1, '[SSL: CERTIFICATE_VERIFY_FAILED] certificate verify failed: self signed certificate in certificate chain (_ssl.c:1002)')))
news.rst:48: [broken] https://github.com/bloomberg/pytest-memray/issues/28: HTTPSConnectionPool(host='github.com', port=443): Max retries exceeded with url: /bloomberg/pytest-memray/issues/28 (Caused by SSLError(SSLCertVerificationError(1, '[SSL: CERTIFICATE_VERIFY_FAILED] certificate verify failed: self signed certificate in certificate chain (_ssl.c:1002)')))
news.rst:71: [broken] https://github.com/bloomberg/pytest-memray/issues/3: HTTPSConnectionPool(host='github.com', port=443): Max retries exceeded with url: /bloomberg/pytest-memray/issues/3 (Caused by SSLError(SSLCertVerificationError(1, '[SSL: CERTIFICATE_VERIFY_FAILED] certificate verify failed: self signed certificate in certificate chain (_ssl.c:1002)')))
news.rst:63: [broken] https://github.com/bloomberg/pytest-memray/issues/5: HTTPSConnectionPool(host='github.com', port=443): Max retries exceeded with url: /bloomberg/pytest-memray/issues/5 (Caused by SSLError(SSLCertVerificationError(1, '[SSL: CERTIFICATE_VERIFY_FAILED] certificate verify failed: self signed certificate in certificate chain (_ssl.c:1002)')))
news.rst:56: [broken] https://github.com/bloomberg/pytest-memray/issues/30: HTTPSConnectionPool(host='github.com', port=443): Max retries exceeded with url: /bloomberg/pytest-memray/issues/30 (Caused by SSLError(SSLCertVerificationError(1, '[SSL: CERTIFICATE_VERIFY_FAILED] certificate verify failed: self signed certificate in certificate chain (_ssl.c:1002)')))
news.rst:13: [broken] https://github.com/bloomberg/pytest-memray/issues/57: HTTPSConnectionPool(host='github.com', port=443): Max retries exceeded with url: /bloomberg/pytest-memray/issues/57 (Caused by SSLError(SSLCertVerificationError(1, '[SSL: CERTIFICATE_VERIFY_FAILED] certificate verify failed: self signed certificate in certificate chain (_ssl.c:1002)')))
news.rst:14: [broken] https://github.com/bloomberg/pytest-memray/issues/58: HTTPSConnectionPool(host='github.com', port=443): Max retries exceeded with url: /bloomberg/pytest-memray/issues/58 (Caused by SSLError(SSLCertVerificationError(1, '[SSL: CERTIFICATE_VERIFY_FAILED] certificate verify failed: self signed certificate in certificate chain (_ssl.c:1002)')))
news.rst:41: [broken] https://github.com/gaborbernat: HTTPSConnectionPool(host='github.com', port=443): Max retries exceeded with url: /gaborbernat (Caused by SSLError(SSLCertVerificationError(1, '[SSL: CERTIFICATE_VERIFY_FAILED] certificate verify failed: self signed certificate in certificate chain (_ssl.c:1002)')))
news.rst:63: [broken] https://github.com/petr-tik: HTTPSConnectionPool(host='github.com', port=443): Max retries exceeded with url: /petr-tik (Caused by SSLError(SSLCertVerificationError(1, '[SSL: CERTIFICATE_VERIFY_FAILED] certificate verify failed: self signed certificate in certificate chain (_ssl.c:1002)')))
news.rst:18: [broken] https://github.com/bloomberg/pytest-memray/issues/60: HTTPSConnectionPool(host='github.com', port=443): Max retries exceeded with url: /bloomberg/pytest-memray/issues/60 (Caused by SSLError(SSLCertVerificationError(1, '[SSL: CERTIFICATE_VERIFY_FAILED] certificate verify failed: self signed certificate in certificate chain (_ssl.c:1002)')))
